<sdf version='1.9'>
  <world name='empty'>
    <physics name='1ms' type='ignored'>
      <max_step_size>0.001</max_step_size>
      <real_time_factor>1</real_time_factor>
      <real_time_update_rate>1000</real_time_update_rate>
    </physics>
    <plugin name='gz::sim::systems::Physics' filename='gz-sim-physics-system'/>
    <plugin name='gz::sim::systems::UserCommands' filename='gz-sim-user-commands-system'/>
    <plugin name='gz::sim::systems::SceneBroadcaster' filename='gz-sim-scene-broadcaster-system'/>
    <plugin name='gz::sim::systems::Contact' filename='gz-sim-contact-system'/>
    <plugin name='gz::sim::systems::Sensors' filename='ignition-gazebo6-sensors-system'/>
    <gravity>0 0 -9.8000000000000007</gravity>
    <magnetic_field>5.5644999999999998e-06 2.2875799999999999e-05 -4.2388400000000002e-05</magnetic_field>
    <atmosphere type='adiabatic'/>
    <scene>
      <ambient>0.400000006 0.400000006 0.400000006 1</ambient>
      <background>0.699999988 0.699999988 0.699999988 1</background>
      <shadows>true</shadows>
    </scene>
    <model name='ground_plane'>
      <static>true</static>
      <link name='link'>
        <collision name='collision'>
          <geometry>
            <plane>
              <normal>0 0 1</normal>
              <size>100 100</size>
            </plane>
          </geometry>
          <surface>
            <friction>
              <ode/>
            </friction>
            <bounce/>
            <contact/>
          </surface>
        </collision>
        <visual name='visual'>
          <geometry>
            <plane>
              <normal>0 0 1</normal>
              <size>100 100</size>
            </plane>
          </geometry>
          <material>
            <ambient>0.800000012 0.800000012 0.800000012 1</ambient>
            <diffuse>0.800000012 0.800000012 0.800000012 1</diffuse>
            <specular>0.800000012 0.800000012 0.800000012 1</specular>
          </material>
        </visual>
        <pose>0 0 0 0 0 0</pose>
        <inertial>
          <pose>0 0 0 0 0 0</pose>
          <mass>1</mass>
          <inertia>
            <ixx>1</ixx>
            <ixy>0</ixy>
            <ixz>0</ixz>
            <iyy>1</iyy>
            <iyz>0</iyz>
            <izz>1</izz>
          </inertia>
        </inertial>
        <enable_wind>false</enable_wind>
      </link>
      <pose>0 0 0 0 0 0</pose>
      <self_collide>false</self_collide>
    </model>
    <model name='marble_husky_sensor_config_5'>
      <plugin name='ignition::gazebo::systems::DiffDrive' filename='libignition-gazebo-diff-drive-system.so'>
        <left_joint>front_left_wheel_joint</left_joint>
        <left_joint>rear_left_wheel_joint</left_joint>
        <right_joint>front_right_wheel_joint</right_joint>
        <right_joint>rear_right_wheel_joint</right_joint>
        <wheel_separation>0.55</wheel_separation>
        <wheel_radius>0.1651</wheel_radius>
        <odom_publish_frequency>100</odom_publish_frequency>
        <topic>cmd_vel</topic>
      </plugin>
      <link name='base_link'>
        <inertial>
          <pose>0 0 0.13228000000000001 0 0 0</pose>
          <mass>50</mass>
          <inertia>
            <ixx>0.61539699999999997</ixx>
            <ixy>-0.0240585</ixy>
            <ixz>-0.120749</ixz>
            <iyy>1.7538800000000001</iyy>
            <iyz>-0.0028322</iyz>
            <izz>2.0364100000000001</izz>
          </inertia>
        </inertial>
        <collision name='base_link_collision'>
          <pose>0 0 0.12 0 0 0</pose>
          <geometry>
            <box>
              <size>0.98740000000000006 0.57089999999999996 0.050000000000000003</size>
            </box>
          </geometry>
          <surface>
            <friction>
              <ode/>
            </friction>
            <bounce/>
            <contact/>
          </surface>
        </collision>
        <collision name='base_link_collision_bottom'>
          <pose>0 0 0.045999999999999999 0 0 0</pose>
          <geometry>
            <box>
              <size>0.80000000000000004 0.57089999999999996 0.095000000000000001</size>
            </box>
          </geometry>
          <surface>
            <friction>
              <ode/>
            </friction>
            <bounce/>
            <contact/>
          </surface>
        </collision>
        <collision name='base_link_collision_1'>
          <pose>0 0 0.18562500000000001 0 0 0</pose>
          <geometry>
            <box>
              <size>0.78991999999999996 0.57089999999999996 0.12375</size>
            </box>
          </geometry>
          <surface>
            <friction>
              <ode/>
            </friction>
            <bounce/>
            <contact/>
          </surface>
        </collision>
        <visual name='base_link_visual'>
          <geometry>
            <mesh>
              <scale>1 1 1</scale>
              <uri>https://fuel.ignitionrobotics.org/1.0/OpenRobotics/models/MARBLE_HUSKY_SENSOR_CONFIG_4/tip/files/meshes/base_link.dae</uri>
            </mesh>
          </geometry>
        </visual>
        <visual name='base_link_fixed_joint_lump__front_bumper_link_visual_3'>
          <pose>0.47999999999999998 0 0.090999999999999998 0 0 0</pose>
          <geometry>
            <mesh>
              <scale>1 1 1</scale>
              <uri>https://fuel.ignitionrobotics.org/1.0/OpenRobotics/models/MARBLE_HUSKY_SENSOR_CONFIG_4/tip/files/meshes/bumper.dae</uri>
            </mesh>
          </geometry>
        </visual>
        <visual name='base_link_fixed_joint_lump__rear_bumper_link_visual_4'>
          <pose>-0.47999999999999998 0 0.090999999999999998 0 0 3.1415899999999999</pose>
          <geometry>
            <mesh>
              <scale>1 1 1</scale>
              <uri>https://fuel.ignitionrobotics.org/1.0/OpenRobotics/models/MARBLE_HUSKY_SENSOR_CONFIG_4/tip/files/meshes/bumper.dae</uri>
            </mesh>
          </geometry>
        </visual>
        <visual name='base_link_fixed_joint_lump__top_chassis_link_visual_5'>
          <geometry>
            <mesh>
              <scale>1 1 1</scale>
              <uri>https://fuel.ignitionrobotics.org/1.0/OpenRobotics/models/MARBLE_HUSKY_SENSOR_CONFIG_4/tip/files/meshes/top_chassis.dae</uri>
            </mesh>
          </geometry>
        </visual>
        <visual name='base_link_fixed_joint_lump__user_rail_link_visual_13'>
          <pose>0.27200000000000002 0 0.245 0 0 0</pose>
          <geometry>
            <mesh>
              <scale>1 1 1</scale>
              <uri>https://fuel.ignitionrobotics.org/1.0/OpenRobotics/models/MARBLE_HUSKY_SENSOR_CONFIG_4/tip/files/meshes/user_rail.dae</uri>
            </mesh>
          </geometry>
        </visual>
        <gravity>true</gravity>
        <velocity_decay/>
        <sensor name='imu_sensor' type='imu'>
          <pose>0 0 0 0 0 0</pose>
          <topic>/imu</topic>
          <update_rate>200</update_rate>
          <enable_metrics>false</enable_metrics>
          <imu>
            <orientation_reference_frame>
              <localization>CUSTOM</localization>
              <custom_rpy>0 0 0</custom_rpy>
              <grav_dir_x>1 0 0</grav_dir_x>
            </orientation_reference_frame>
            <angular_velocity>
              <x>
                <noise type='gaussian'>
                  <mean>0</mean>
                  <stddev>0.0089999999999999993</stddev>
                  <bias_mean>0.00075000000000000002</bias_mean>
                  <bias_stddev>0.0050000000000000001</bias_stddev>
                  <dynamic_bias_stddev>2.0000000000000002e-05</dynamic_bias_stddev>
                  <dynamic_bias_correlation_time>400</dynamic_bias_correlation_time>
                  <precision>0.00025000000000000001</precision>
                </noise>
              </x>
              <y>
                <noise type='gaussian'>
                  <mean>0</mean>
                  <stddev>0.0089999999999999993</stddev>
                  <bias_mean>0.00075000000000000002</bias_mean>
                  <bias_stddev>0.0050000000000000001</bias_stddev>
                  <dynamic_bias_stddev>2.0000000000000002e-05</dynamic_bias_stddev>
                  <dynamic_bias_correlation_time>400</dynamic_bias_correlation_time>
                  <precision>0.00025000000000000001</precision>
                </noise>
              </y>
              <z>
                <noise type='gaussian'>
                  <mean>0</mean>
                  <stddev>0.0089999999999999993</stddev>
                  <bias_mean>0.00075000000000000002</bias_mean>
                  <bias_stddev>0.0050000000000000001</bias_stddev>
                  <dynamic_bias_stddev>2.0000000000000002e-05</dynamic_bias_stddev>
                  <dynamic_bias_correlation_time>400</dynamic_bias_correlation_time>
                  <precision>0.00025000000000000001</precision>
                </noise>
              </z>
            </angular_velocity>
            <linear_acceleration>
              <x>
                <noise type='gaussian'>
                  <mean>0</mean>
                  <stddev>0.021000000000000001</stddev>
                  <bias_mean>0.050000000000000003</bias_mean>
                  <bias_stddev>0.0074999999999999997</bias_stddev>
                  <dynamic_bias_stddev>0.00037500000000000001</dynamic_bias_stddev>
                  <dynamic_bias_correlation_time>175</dynamic_bias_correlation_time>
                  <precision>0.0050000000000000001</precision>
                </noise>
              </x>
              <y>
                <noise type='gaussian'>
                  <mean>0</mean>
                  <stddev>0.021000000000000001</stddev>
                  <bias_mean>0.050000000000000003</bias_mean>
                  <bias_stddev>0.0074999999999999997</bias_stddev>
                  <dynamic_bias_stddev>0.00037500000000000001</dynamic_bias_stddev>
                  <dynamic_bias_correlation_time>175</dynamic_bias_correlation_time>
                  <precision>0.0050000000000000001</precision>
                </noise>
              </y>
              <z>
                <noise type='gaussian'>
                  <mean>0</mean>
                  <stddev>0.021000000000000001</stddev>
                  <bias_mean>0.050000000000000003</bias_mean>
                  <bias_stddev>0.0074999999999999997</bias_stddev>
                  <dynamic_bias_stddev>0.00037500000000000001</dynamic_bias_stddev>
                  <dynamic_bias_correlation_time>175</dynamic_bias_correlation_time>
                  <precision>0.0050000000000000001</precision>
                </noise>
              </z>
            </linear_acceleration>
            <enable_orientation>true</enable_orientation>
          </imu>
        </sensor>
        <light name='flashlight_flashlight_light_source_lamp_light_front' type='spot'>
          <pose>0.51790000000000003 0 0.53717999999999999 -2.999999999991991e-06 1.5706900000000439 -3.1415899999999999</pose>
          <cast_shadows>false</cast_shadows>
          <intensity>1</intensity>
          <direction>0 0 -1</direction>
          <diffuse>0.800000012 0.800000012 0.5 1</diffuse>
          <specular>0.800000012 0.800000012 0.5 1</specular>
          <attenuation>
            <range>35</range>
            <linear>0</linear>
            <constant>0.10000000149011612</constant>
            <quadratic>0.0024999999441206455</quadratic>
          </attenuation>
          <spot>
            <inner_angle>1.7999999523162842</inner_angle>
            <outer_angle>1.8999999761581421</outer_angle>
            <falloff>1</falloff>
          </spot>
        </light>
        <light name='flashlight_flashlight_light_source_lamp_light_left' type='spot'>
          <pose>0.43790000000000001 0.12 0.53717999999999999 1.5708 0 0</pose>
          <cast_shadows>false</cast_shadows>
          <intensity>1</intensity>
          <direction>0 0 -1</direction>
          <diffuse>0.800000012 0.800000012 0.5 1</diffuse>
          <specular>0.800000012 0.800000012 0.5 1</specular>
          <attenuation>
            <range>35</range>
            <linear>0</linear>
            <constant>0.10000000149011612</constant>
            <quadratic>0.0024999999441206455</quadratic>
          </attenuation>
          <spot>
            <inner_angle>1.7999999523162842</inner_angle>
            <outer_angle>1.8999999761581421</outer_angle>
            <falloff>1</falloff>
          </spot>
        </light>
        <light name='flashlight_flashlight_light_source_lamp_light_right' type='spot'>
          <pose>0.43790000000000001 -0.12 0.53717999999999999 -1.5708 0 0</pose>
          <cast_shadows>false</cast_shadows>
          <intensity>1</intensity>
          <direction>0 0 -1</direction>
          <diffuse>0.800000012 0.800000012 0.5 1</diffuse>
          <specular>0.800000012 0.800000012 0.5 1</specular>
          <attenuation>
            <range>35</range>
            <linear>0</linear>
            <constant>0.10000000149011612</constant>
            <quadratic>0.0024999999441206455</quadratic>
          </attenuation>
          <spot>
            <inner_angle>1.7999999523162842</inner_angle>
            <outer_angle>1.8999999761581421</outer_angle>
            <falloff>1</falloff>
          </spot>
        </light>
        <light name='flashlight_flashlight_light_source_lamp_light_back' type='spot'>
          <pose>0.3579 0 0.53717999999999999 -2.999999999991991e-06 -1.5706900000000439 3.1415899999999999</pose>
          <cast_shadows>false</cast_shadows>
          <intensity>1</intensity>
          <direction>0 0 -1</direction>
          <diffuse>0.800000012 0.800000012 0.5 1</diffuse>
          <specular>0.800000012 0.800000012 0.5 1</specular>
          <attenuation>
            <range>35</range>
            <linear>0</linear>
            <constant>0.10000000149011612</constant>
            <quadratic>0.0024999999441206455</quadratic>
          </attenuation>
          <spot>
            <inner_angle>1.7999999523162842</inner_angle>
            <outer_angle>1.8999999761581421</outer_angle>
            <falloff>1</falloff>
          </spot>
        </light>
        <pose>0 0 0 0 0 0</pose>
        <enable_wind>false</enable_wind>
      </link>
      <link name='front_left_wheel_link'>
        <pose>0.25600000000000001 0.28540000000000004 0.032820999999999795 -3.1415895917796886 0.12566007365630427 -3.1415900254553457</pose>
        <inertial>
          <mass>2.637</mass>
          <inertia>
            <ixx>0.024670000000000001</ixx>
            <ixy>0</ixy>
            <ixz>0</ixz>
            <iyy>0.044110000000000003</iyy>
            <iyz>0</iyz>
            <izz>0.024670000000000001</izz>
          </inertia>
          <pose>0 0 0 0 0 0</pose>
        </inertial>
        <collision name='front_left_wheel_link_collision'>
          <pose>0 0 0 1.5707963267948963 0 0</pose>
          <geometry>
            <cylinder>
              <length>0.1143</length>
              <radius>0.1651</radius>
            </cylinder>
          </geometry>
          <surface>
            <contact>
              <ode>
                <kp>10000000</kp>
                <kd>1</kd>
              </ode>
            </contact>
            <friction>
              <ode>
                <mu>0.5</mu>
                <mu2>1</mu2>
                <slip1>0.00062</slip1>
                <slip2>0</slip2>
                <fdir1>0 0 1</fdir1>
              </ode>
            </friction>
            <bounce/>
          </surface>
        </collision>
        <visual name='front_left_wheel_link_visual'>
          <geometry>
            <mesh>
              <scale>1 1 1</scale>
              <uri>https://fuel.ignitionrobotics.org/1.0/OpenRobotics/models/MARBLE_HUSKY_SENSOR_CONFIG_4/tip/files/meshes/wheel.dae</uri>
            </mesh>
          </geometry>
        </visual>
        <gravity>true</gravity>
        <velocity_decay/>
        <enable_wind>false</enable_wind>
      </link>
      <joint name='front_left_wheel_joint' type='revolute'>
        <child>front_left_wheel_link</child>
        <parent>base_link</parent>
        <axis>
          <xyz>5.2939559203393771e-22 1 4.2351647362715012e-22</xyz>
          <limit>
            <lower>-10000000000000000</lower>
            <upper>10000000000000000</upper>
            <effort>inf</effort>
            <velocity>inf</velocity>
            <stiffness>100000000</stiffness>
            <dissipation>1</dissipation>
          </limit>
          <dynamics>
            <spring_reference>0</spring_reference>
            <spring_stiffness>0</spring_stiffness>
            <damping>0</damping>
            <friction>0</friction>
          </dynamics>
        </axis>
        <pose>5.5511199999999995e-17 1.11022e-16 -1.47072e-16 4.2351600000000001e-22 7.9076099999999995e-17 -5.5586499999999999e-22</pose>
      </joint>
      <link name='front_right_wheel_link'>
        <pose>0.25600000000000012 -0.28539999999999993 0.032820000000000293 -2.9500959194699759e-06 -0.52264121159849575 3.4584564441642054e-06</pose>
        <inertial>
          <mass>2.637</mass>
          <inertia>
            <ixx>0.024670000000000001</ixx>
            <ixy>0</ixy>
            <ixz>0</ixz>
            <iyy>0.044110000000000003</iyy>
            <iyz>0</iyz>
            <izz>0.024670000000000001</izz>
          </inertia>
          <pose>0 0 0 0 0 0</pose>
        </inertial>
        <collision name='front_right_wheel_link_collision'>
          <pose>0 0 0 1.5707963267948963 0 0</pose>
          <geometry>
            <cylinder>
              <length>0.1143</length>
              <radius>0.1651</radius>
            </cylinder>
          </geometry>
          <surface>
            <contact>
              <ode>
                <kp>10000000</kp>
                <kd>1</kd>
              </ode>
            </contact>
            <friction>
              <ode>
                <mu>0.5</mu>
                <mu2>1</mu2>
                <slip1>0.00062</slip1>
                <slip2>0</slip2>
                <fdir1>0 0 1</fdir1>
              </ode>
            </friction>
            <bounce/>
          </surface>
        </collision>
        <visual name='front_right_wheel_link_visual'>
          <geometry>
            <mesh>
              <scale>1 1 1</scale>
              <uri>https://fuel.ignitionrobotics.org/1.0/OpenRobotics/models/MARBLE_HUSKY_SENSOR_CONFIG_4/tip/files/meshes/wheel.dae</uri>
            </mesh>
          </geometry>
        </visual>
        <gravity>true</gravity>
        <velocity_decay/>
        <enable_wind>false</enable_wind>
      </link>
      <joint name='front_right_wheel_joint' type='revolute'>
        <child>front_right_wheel_link</child>
        <parent>base_link</parent>
        <axis>
          <xyz>-5.2939559203393771e-23 1 1.9820989604989484e-39</xyz>
          <limit>
            <lower>-10000000000000000</lower>
            <upper>10000000000000000</upper>
            <effort>inf</effort>
            <velocity>inf</velocity>
            <stiffness>100000000</stiffness>
            <dissipation>1</dissipation>
          </limit>
          <dynamics>
            <spring_reference>0</spring_reference>
            <spring_stiffness>0</spring_stiffness>
            <damping>0</damping>
            <friction>0</friction>
          </dynamics>
        </axis>
        <pose>-1.38778e-16 -5.5511199999999995e-17 -5.5511199999999995e-17 0 2.7215599999999999e-17 0</pose>
      </joint>
      <link name='rear_left_wheel_link'>
        <pose>-0.25599999999999995 0.28539999999999993 0.032820000000000127 -2.7354456317663443e-06 -0.46203272735331002 -1.9964225480507704e-06</pose>
        <inertial>
          <mass>2.637</mass>
          <inertia>
            <ixx>0.024670000000000001</ixx>
            <ixy>0</ixy>
            <ixz>0</ixz>
            <iyy>0.044110000000000003</iyy>
            <iyz>0</iyz>
            <izz>0.024670000000000001</izz>
          </inertia>
          <pose>0 0 0 0 0 0</pose>
        </inertial>
        <collision name='rear_left_wheel_link_collision'>
          <pose>0 0 0 1.5707963267948963 0 0</pose>
          <geometry>
            <cylinder>
              <length>0.1143</length>
              <radius>0.1651</radius>
            </cylinder>
          </geometry>
          <surface>
            <contact>
              <ode>
                <kp>10000000</kp>
                <kd>1</kd>
              </ode>
            </contact>
            <friction>
              <ode>
                <mu>0.5</mu>
                <mu2>1</mu2>
                <slip1>0.00062</slip1>
                <slip2>0</slip2>
                <fdir1>0 0 1</fdir1>
              </ode>
            </friction>
            <bounce/>
          </surface>
        </collision>
        <visual name='rear_left_wheel_link_visual'>
          <geometry>
            <mesh>
              <scale>1 1 1</scale>
              <uri>https://fuel.ignitionrobotics.org/1.0/OpenRobotics/models/MARBLE_HUSKY_SENSOR_CONFIG_4/tip/files/meshes/wheel.dae</uri>
            </mesh>
          </geometry>
        </visual>
        <gravity>true</gravity>
        <velocity_decay/>
        <enable_wind>false</enable_wind>
      </link>
      <joint name='rear_left_wheel_joint' type='revolute'>
        <child>rear_left_wheel_link</child>
        <parent>base_link</parent>
        <axis>
          <xyz>0 1 0</xyz>
          <limit>
            <lower>-10000000000000000</lower>
            <upper>10000000000000000</upper>
            <effort>inf</effort>
            <velocity>inf</velocity>
            <stiffness>100000000</stiffness>
            <dissipation>1</dissipation>
          </limit>
          <dynamics>
            <spring_reference>0</spring_reference>
            <spring_stiffness>0</spring_stiffness>
            <damping>0</damping>
            <friction>0</friction>
          </dynamics>
        </axis>
        <pose>-8.3266699999999998e-17 -5.5511199999999995e-17 0 0 1.46993e-17 0</pose>
      </joint>
      <link name='rear_right_wheel_link'>
        <pose>-0.25599999999999995 -0.28540000000000004 0.032820000000000099 3.0671794590165351e-06 -0.27619855880138716 -1.1853225435347709e-06</pose>
        <inertial>
          <mass>2.637</mass>
          <inertia>
            <ixx>0.024670000000000001</ixx>
            <ixy>0</ixy>
            <ixz>0</ixz>
            <iyy>0.044110000000000003</iyy>
            <iyz>0</iyz>
            <izz>0.024670000000000001</izz>
          </inertia>
          <pose>0 0 0 0 0 0</pose>
        </inertial>
        <collision name='rear_right_wheel_link_collision'>
          <pose>0 0 0 1.5707963267948963 0 0</pose>
          <geometry>
            <cylinder>
              <length>0.1143</length>
              <radius>0.1651</radius>
            </cylinder>
          </geometry>
          <surface>
            <contact>
              <ode>
                <kp>10000000</kp>
                <kd>1</kd>
              </ode>
            </contact>
            <friction>
              <ode>
                <mu>0.5</mu>
                <mu2>1</mu2>
                <slip1>0.00062</slip1>
                <slip2>0</slip2>
                <fdir1>0 0 1</fdir1>
              </ode>
            </friction>
            <bounce/>
          </surface>
        </collision>
        <visual name='rear_right_wheel_link_visual'>
          <geometry>
            <mesh>
              <scale>1 1 1</scale>
              <uri>https://fuel.ignitionrobotics.org/1.0/OpenRobotics/models/MARBLE_HUSKY_SENSOR_CONFIG_4/tip/files/meshes/wheel.dae</uri>
            </mesh>
          </geometry>
        </visual>
        <gravity>true</gravity>
        <velocity_decay/>
        <enable_wind>false</enable_wind>
      </link>
      <joint name='rear_right_wheel_joint' type='revolute'>
        <child>rear_right_wheel_link</child>
        <parent>base_link</parent>
        <axis>
          <xyz>2.1175823681357508e-22 1 2.1175823681357504e-22</xyz>
          <limit>
            <lower>-10000000000000000</lower>
            <upper>10000000000000000</upper>
            <effort>inf</effort>
            <velocity>inf</velocity>
            <stiffness>100000000</stiffness>
            <dissipation>1</dissipation>
          </limit>
          <dynamics>
            <spring_reference>0</spring_reference>
            <spring_stiffness>0</spring_stiffness>
            <damping>0</damping>
            <friction>0</friction>
          </dynamics>
        </axis>
        <pose>8.3266699999999998e-17 0 2.7755599999999997e-17 -3.9704700000000002e-23 1.2560599999999999e-16 -1.05879e-22</pose>
      </joint>
      <pose>0 0 0 0 0 0</pose>
      <static>false</static>
      <self_collide>false</self_collide>
      <plugin name='gz::sim::systems::PosePublisher' filename='gz-sim-pose-publisher-system'>
        <use_pose_vector_msg>true</use_pose_vector_msg>
        <publish_nested_model_pose>true</publish_nested_model_pose>
      </plugin>
    </model> 
    <light name='sun' type='directional'>
      <pose>0 0 10 0 0 0</pose>
      <cast_shadows>true</cast_shadows>
      <intensity>1</intensity>
      <direction>-0.5 0.10000000000000001 -0.90000000000000002</direction>
      <diffuse>0.800000012 0.800000012 0.800000012 1</diffuse>
      <specular>0.200000003 0.200000003 0.200000003 1</specular>
      <attenuation>
        <range>1000</range>
        <linear>0.0099999997764825821</linear>
        <constant>0.89999997615814209</constant>
        <quadratic>0.0010000000474974513</quadratic>
      </attenuation>
      <spot>
        <inner_angle>0</inner_angle>
        <outer_angle>0</outer_angle>
        <falloff>0</falloff>
      </spot>
    </light>
  </world>
</sdf>
